Workbook

Sheet PESQUISA
A1: CNAE | B1: DESCRIÇÃO | C1: VALOR | E1: CNAE a TRIBUTAR
B2: =IF(A2="","",VLOOKUP(A2,'ANEXO CTMI'!A$1:P$2043,8)) | C2: =IF(A2="","",VLOOKUP(A2,'ANEXO CTMI'!A$1:P$2043,10)) | D2: =IF(A2="","",MAX(C$2:C$41)) | E2: =IF(A2="","",IF(C2=D2,"X",""))
B3: =IF(A3="","",VLOOKUP(A3,'ANEXO CTMI'!A$1:P$2043,8)) | C3: =IF(A3="","",VLOOKUP(A3,'ANEXO CTMI'!A$1:P$2043,10)) | D3: =IF(A3="","",MAX(C$2:C$41)) | E3: =IF(A3="","",IF(C3=D3,"X",""))
B4: =IF(A4="","",VLOOKUP(A4,'ANEXO CTMI'!A$1:P$2043,8)) | C4: =IF(A4="","",VLOOKUP(A4,'ANEXO CTMI'!A$1:P$2043,10)) | D4: =IF(A4="","",MAX(C$2:C$41)) | E4: =IF(A4="","",IF(C4=D4,"X",""))
B5: =IF(A5="","",VLOOKUP(A5,'ANEXO CTMI'!A$1:P$2043,8)) | C5: =IF(A5="","",VLOOKUP(A5,'ANEXO CTMI'!A$1:P$2043,10)) | D5: =IF(A5="","",MAX(C$2:C$41)) | E5: =IF(A5="","",IF(C5=D5,"X",""))
B6: =IF(A6="","",VLOOKUP(A6,'ANEXO CTMI'!A$1:P$2043,8)) | C6: =IF(A6="","",VLOOKUP(A6,'ANEXO CTMI'!A$1:P$2043,10)) | D6: =IF(A6="","",MAX(C$2:C$41)) | E6: =IF(A6="","",IF(C6=D6,"X",""))
B7: =IF(A7="","",VLOOKUP(A7,'ANEXO CTMI'!A$1:P$2043,8)) | C7: =IF(A7="","",VLOOKUP(A7,'ANEXO CTMI'!A$1:P$2043,10)) | D7: =IF(A7="","",MAX(C$2:C$41)) | E7: =IF(A7="","",IF(C7=D7,"X",""))
B8: =IF(A8="","",VLOOKUP(A8,'ANEXO CTMI'!A$1:P$2043,8)) | C8: =IF(A8="","",VLOOKUP(A8,'ANEXO CTMI'!A$1:P$2043,10)) | D8: =IF(A8="","",MAX(C$2:C$41)) | E8: =IF(A8="","",IF(C8=D8,"X",""))
B9: =IF(A9="","",VLOOKUP(A9,'ANEXO CTMI'!A$1:P$2043,8)) | C9: =IF(A9="","",VLOOKUP(A9,'ANEXO CTMI'!A$1:P$2043,10)) | D9: =IF(A9="","",MAX(C$2:C$41)) | E9: =IF(A9="","",IF(C9=D9,"X",""))
B10: =IF(A10="","",VLOOKUP(A10,'ANEXO CTMI'!A$1:P$2043,8)) | C10: =IF(A10="","",VLOOKUP(A10,'ANEXO CTMI'!A$1:P$2043,10)) | D10: =IF(A10="","",MAX(C$2:C$41)) | E10: =IF(A10="","",IF(C10=D10,"X",""))
B11: =IF(A11="","",VLOOKUP(A11,'ANEXO CTMI'!A$1:P$2043,8)) | C11: =IF(A11="","",VLOOKUP(A11,'ANEXO CTMI'!A$1:P$2043,10)) | D11: =IF(A11="","",MAX(C$2:C$41)) | E11: =IF(A11="","",IF(C11=D11,"X",""))
B12: =IF(A12="","",VLOOKUP(A12,'ANEXO CTMI'!A$1:P$2043,8)) | C12: =IF(A12="","",VLOOKUP(A12,'ANEXO CTMI'!A$1:P$2043,10)) | D12: =IF(A12="","",MAX(C$2:C$41)) | E12: =IF(A12="","",IF(C12=D12,"X",""))
B13: =IF(A13="","",VLOOKUP(A13,'ANEXO CTMI'!A$1:P$2043,8)) | C13: =IF(A13="","",VLOOKUP(A13,'ANEXO CTMI'!A$1:P$2043,10)) | D13: =IF(A13="","",MAX(C$2:C$41)) | E13: =IF(A13="","",IF(C13=D13,"X",""))
... B41: =IF(A41="","",VLOOKUP(A41,'ANEXO CTMI'!A$1:P$2043,8)) | C41: =IF(A41="","",VLOOKUP(A41,'ANEXO CTMI'!A$1:P$2043,10)) | D41: =IF(A41="","",MAX(C$2:C$41)) | E41: =IF(A41="","",IF(C41=D41,"X",""))

Sheet ANEXO CTMI
A1: 0 | C1: ANEXO | D1: setor | E1: tipo | F1: esp | H1: RETORNO PARA CODCONT | I1: unid | J1: UFITA/ANO ALVARÁ | L1: Mesnsal | M1: tempo | N1: OBS
A2: 999 | H2: DESCRIÇÃO DA ATIVIDADE | K2: Base de Cálculo | L2: % ISS EMP /AUT | M2: ISS em UFITAS (MENSAL)
A3: 111301 | G3: T.F.I.F. | H3: Cultivo de arroz | J3: 31.68
A4: 111302 | G4: T.F.I.F. | H4: Cultivo de milho | J4: 31.68
A5: 111303 | G5: T.F.I.F. | H5: Cultivo de trigo | J5: 31.68
A6: 111399 | G6: T.F.I.F. | H6: Cultivo de outros cereais não especificados anteriormente | J6: 31.68
A7: 112101 | G7: T.F.I.F. | H7: Cultivo de algodão herbáceo | J7: 31.68
A8: 112102 | G8: T.F.I.F. | H8: Cultivo de juta | J8: 31.68
A9: 112199 | G9: T.F.I.F. | H9: Cultivo de outras fibras de lavoura temporária não especificadas anteriormente | J9: 31.68
A10: 113000 | G10: T.F.I.F. | H10: Cultivo de cana-de-açúcar | J10: 31.68
A11: 114800 | G11: T.F.I.F. | H11: Cultivo de fumo | J11: 31.68
A12: 115600 | G12: T.F.I.F. | H12: Cultivo de soja | J12: 31.68
A13: 116401 | G13: T.F.I.F. | H13: Cultivo de amendoim | J13: 31.68
A14: 116402 | G14: T.F.I.F. | H14: Cultivo de girassol | J14: 31.68
... A74: 159899 | G74: T.F.I.F. | H74: Criação de outros animais não especificados anteriormente | J74: 31.68
A75: 161001 | G75: T.F.I.F. | H75: Serviço de pulverização e controle de pragas agrícolas | J75: 12.67 | L75: 2
A76: 161002 | G76: T.F.I.F. | H76: Serviço de poda de árvores para lavouras | J76: 12.67 | L76: 3
A77: 161003 | G77: T.F.I.F. | H77: Serviço de preparação de terreno, cultivo e colheita | J77: 0
A78: 161099 | G78: T.F.I.F. | H78: Atividades de apoio à agricultura não especificadas anteriormente | J78: 31.68 | L78: 5
A79: 162801 | G79: T.F.I.F. | H79: Serviço de inseminação artificial em animais | J79: 31.68 | L79: 5
A80: 162802 | G80: T.F.I.F. | H80: Serviço de tosquiamento de ovinos | J80: 31.68 | L80: 5
A81: 162803 | G81: T.F.I.F. | H81: Serviço de manejo de animais | J81: 31.68 | L81: 5
A82: 162899 | G82: T.F.I.F. | H82: Atividades de apoio à pecuária não especificadas anteriormente | J82: 31.68 | L82: 5
A83: 163600 | G83: T.F.I.F. | H83: Atividades de pós-colheita | J83: 0
A84: 170900 | G84: T.F.I.F. | H84: Caça e serviços relacionados | J84: 31.68 | L84: 5
A85: 210101 | G85: T.F.I.F. | H85: Cultivo de eucalipto | J85: 31.68
A86: 210102 | G86: T.F.I.F. | H86: Cultivo de acácia-negra | J86: 31.68
A87: 210103 | G87: T.F.I.F. | H87: Cultivo de pinus | J87: 31.68
A88: 210104 | G88: T.F.I.F. | H88: Cultivo de teca | J88: 31.68
A89: 210105 | G89: T.F.I.F. | H89: Cultivo de espécies madeireiras, exceto eucalipto, acácia-negra, pinus e teca | J89: 31.68
A90: 210106 | G90: T.F.I.F. | H90: Cultivo de mudas em viveiros florestais | J90: 31.68 | L90: 2
A91: 210107 | G91: T.F.I.F. | H91: Extração de madeira em florestas plantadas | J91: 31.68 | L91: 5
A92: 210108 | G92: T.F.I.F. | H92: Produção de carvão vegetal - florestas plantadas | J92: 31.68 | L92: 5
A93: 210109 | G93: T.F.I.F. | H93: Produção de casca de acácia-negra - florestas plantadas | J93: 31.68 | L93: 5
A94: 210199 | G94: T.F.I.F. | H94: Produção de produtos não-madeireiros não especificados anteriormente em florestas plantadas | J94: 31.68 | L94: 5
A95: 220901 | G95: T.F.I.F. | H95: Extração de madeira em florestas nativas | J95: 31.68 | L95: 5
A96: 220902 | G96: T.F.I.F. | H96: Produção de carvão vegetal - florestas nativas | J96: 31.68 | L96: 5
A97: 220903 | G97: T.F.I.F. | H97: Coleta de castanha-do-pará em florestas nativas | J97: 31.68 | L97: 5
A98: 220904 | G98: T.F.I.F. | H98: Coleta de látex em florestas nativas | J98: 31.68 | L98: 5
A99: 220905 | G99: T.F.I.F. | H99: Coleta de palmito em florestas nativas | J99: 31.68 | L99: 5
...

Sheet ISS 2024
A1: ATIVIDADES | B1: Base de cálculo Estimada - Mensal - UFITAS | C1: ALÍQUOTAS % | D1: ISS EM UFITAS
A2: 1 - Profissionais Autônomos Nível Superior:
A3: a) Médicos, dentistas e veterinários | B3: 1092.41 | C3: 0.035 | D3: 38.23
A4: b) Advogados | B4: 1092.41 | C4: 0.035 | D4: 38.23
A5: c) Engenheiro, Arquitetos | B5: 728.27 | C5: 0.035 | D5: 25.48
A6: d) Administradores, economistas e contadores | B6: 728.27 | C6: 0.035 | D6: 25.48
A7: e) Fisioterapeutas, psicólogos e Terapeutas | B7: 728.27 | C7: 0.035 | D7: 25.48
A8: f) Demais profissionais de nível superior | B8: 582.62 | C8: 0.035 | D8: 20.39
A9: 2 - Profissionais Autônomos Nível Médio:
A10: a) Despachante, representantes e corretores | B10: 509.79 | C10: 0.035 | D10: 17.84
A11: b) Mecânicos | B11: 364.13 | C11: 0.035 | D11: 12.74
A12: c) Demais profissionais de nível médio | B12: 254.89 | C12: 0.035 | D12: 8.92
A13: 3 - Profissionais Autônomos Nível Elementar:
A14: a) Motorista (Qualquer modalidade de transporte, inclusive os motoristas auxiliares) (NR LC 238/2018) | B14: 338.82 | C14: 0.035 | D14: 11.86
A15: b) Monitor de Transporte Escolar (NR LC 238/2018) | B15: 148.66 | C15: 0.035 | D15: 5.2
A16: c) Carpinteiros, bombeiro-hidráulico, pedreiros e marceneiros | B16: 364.13 | C16: 0.035 | D16: 12.74
A17: d) Demais Profissionais de Nível Elementar | B17: 218.48 | C17: 0.035 | D17: 7.64
A18: e) Cobrador do Transporte Complementar (NR LC 238/2018) | B18: 148.66 | C18: 0.035 | D18: 5.2
A19: f) Ajudante de Transporte de Produtos Perigosos (NR LC 238/2018) | B19: 148.66 | C19: 0.035 | D19: 5.2
A20: 4 - Profissionais Autônomos de nível superior, não inscrito no município: (NR LC 057/2006)
A21: a) Engenheiros e Arquitetos, por projeto | B21: 728.27 | C21: 0.05 | D21: 36.41
A22: b) Demais Profissionais de nível superior, por serviço prestados | B22: 728.27 | C22: 0.05 | D22: 36.41
A23: 5 - Sociedade de Profissionais de Nível Superior:
A24: a) Por profissionais habilitado sócio, empregado ou não por profissionais | B24: Aplicar tabela nº 1
A25: 6 - Sociedade de Profissionais de nível médio:
A26: a) Por profissional habilitado, sócio, empregado ou não por profissional | B26: Aplicar tabela nº 2
A27: 7 - Sociedade de Profissionais de nível elementar:
A28: a) Por profissional habilitado, sócio, empregado ou não, por profissional | B28: Aplicar tabela nº 3
A29: 8 - Profissionais autônomos de nível médio, não inscrito no município, por serviços prestados | B29: 254.89 | C29: 0.05 | D29: 12.74
A30: 9 - Profissionais autônomos de nível elementar, não inscrito no Município, por serviços prestados | B30: 218.48 | C30: 0.05 | D30: 10.92
A31: 10 - Escritório de Serviços Contábeis: O valor devido mensalmente, ou não-sócio, empregado, ou não, que prestem serviços em nome do escritório (AC LC 092/2009) | B31: 25.48
A32: 11 - Cartórios (AC LC 240/2018) Preço do Serviço, deduzido dos repasses a terceiros por determinação legal | C32: 0.05
A33: 12 - EMPRESAS: (NR LCs 092/2009 e 240/2018) Base de Cálculo - Preço do Serviço x Alíquota
A34: a) Varrição, coleta, remoção, incineração, tratamento, reciclagem separação e destinação final de lixo, rejeitos e outros resíduos quaisquer (Item 7.09 da lista do art. 47) (NR LC 240/2018) | D34: 0.05
A35: b) Limpeza, manutenção e conservação de vias e logradouros públicos, imóveis, chaminés, piscinas, parques, jardins e congêneres (Item 7.10 da lista do art. 47) (NR LC 240/2018) | D35: 0.05
A36: c) Decoração e jardinagem, inclusive corte e poda de arvores. (Item 7.11 da lista do art. 47) | D36: 0.03
A37: d) Dedetização, desinfecção, desinsetização, imunização, higienização, desratização, pulverização e congêneres (Item 7.13 da lista do art. 47) | D37: 0.02
A38: e) Florestamento, reflorestamento, semeadura, adubação e congêneres. (item 7.16 da lista do art. 47) (NR LC 140/2011) | D38: 0.02
A39: f) Escoramento, contenção de encostas e serviços congêneres. (Item 7.15 da lista do art. 47). (Redação dada pelo art. 24 da Lei Complementar 140/2011) (NR LC 240/2018) | D39: 0.05
A40: g) Acompanhamento e fiscalização da execução de obras de engenharia, arquitetura e urbanismo. (item 7.19 da lista do art. 47) (NR LC 140/2011) | D40: 0.05
...
